Workbook

Sheet ReadMe
A1: KSA Geographic Reference — Regions, Governorates & Centers
A2: English working copy for the development team (GIS / map & geo-database build). Personal identifiers removed.
A4: Purpose | B4: A unified reference file of the Kingdom's official administrative divisions (Region → Governorate → Center) for the technical team to use when building map layers and the geographic database.
A5: Structure | B5: 3 administrative levels per the Regions System (Royal Order A/92, 1412H / 1992): 13 administrative regions, 150 governorates (including the amanahs of region capitals), and 1,404 centers (Category A and Category B).
A6: Sheets | B6: 1) Regions: statistical codes, ISO codes, and capitals. 2) Governorates: names with category and code. 3) Centers: every center linked to its governorate and region. 4) References: official sources and links to boundary data (GeoJSON / Shapefiles).
A7: Coding | B7: Region code (1–13) per the General Authority for Statistics ordering. Governorate code = region code + sequence (e.g., 0101 = Riyadh / Riyadh). Center code = governorate code + sequence (e.g., 0104-003). These codes are internal join keys between the sheets and can be replaced with the National Center for Records (NCAR) coding at final adoption.
A8: Notes for the tech team | B8: • Major cities are not an independent administrative level; each governorate is named after its principal city, and region capitals are listed on the Regions sheet. • Center names in the official source are Arabic-only; the English center names in this file are romanizations for development use — for authoritative geographic matching, use the codes (and the Arabic names in the original registry file). • For spatial boundaries (polygons), use the boundary sources on the References sheet (Admin1 = regions, Admin2 = governorates).
A9: Data caveats | B9: • The number of governorates changes by royal orders (118 → 136 in 2012 → 150 currently); newly established governorates are included (e.g., Al-Adid, Tanumah, Al-Harajah, Al-Amwah, Bahrah). • "Bahrah" appeared in the source as a center despite its upgrade to a governorate — its classification is corrected here. • "Al-Amwah" appeared in the source with the spelling "Al-A mwah". • A final reconciliation against the NCAR coding directory and the Ministry of Interior portal is recommended before launch.
A10: Last updated | B10: 07 July 2026 — compiled from the sources listed on the References sheet.

Sheet Regions
A1: Region Code | B1: Region | C1: ISO 3166-2 | D1: Region Capital | E1: Governorates | F1: Centers | G1: Total Units
A2: 1 | B2: Riyadh | C2: SA-01 | D2: Riyadh | E2: =COUNTIF(Governorates!B:B,A2) -> 23 | F2: =COUNTIF(Centers!B:B,A2) -> 417 | G2: =E2+F2 -> 440
A3: 2 | B3: Makkah Al-Mukarramah | C3: SA-02 | D3: Makkah | E3: =COUNTIF(Governorates!B:B,A3) -> 17 | F3: =COUNTIF(Centers!B:B,A3) -> 126 | G3: =E3+F3 -> 143
A4: 3 | B4: Madinah Al-Munawwarah | C4: SA-03 | D4: Madinah | E4: =COUNTIF(Governorates!B:B,A4) -> 9 | F4: =COUNTIF(Centers!B:B,A4) -> 102 | G4: =E4+F4 -> 111
A5: 4 | B5: Al-Qassim | C5: SA-05 | D5: Buraydah | E5: =COUNTIF(Governorates!B:B,A5) -> 13 | F5: =COUNTIF(Centers!B:B,A5) -> 141 | G5: =E5+F5 -> 154
A6: 5 | B6: Eastern Province | C6: SA-04 | D6: Dammam | E6: =COUNTIF(Governorates!B:B,A6) -> 12 | F6: =COUNTIF(Centers!B:B,A6) -> 111 | G6: =E6+F6 -> 123
A7: 6 | B7: Aseer | C7: SA-14 | D7: Abha | E7: =COUNTIF(Governorates!B:B,A7) -> 18 | F7: =COUNTIF(Centers!B:B,A7) -> 122 | G7: =E7+F7 -> 140
A8: 7 | B8: Tabuk | C8: SA-07 | D8: Tabuk | E8: =COUNTIF(Governorates!B:B,A8) -> 7 | F8: =COUNTIF(Centers!B:B,A8) -> 85 | G8: =E8+F8 -> 92
A9: 8 | B9: Hail | C9: SA-06 | D9: Hail | E9: =COUNTIF(Governorates!B:B,A9) -> 9 | F9: =COUNTIF(Centers!B:B,A9) -> 107 | G9: =E9+F9 -> 116
A10: 9 | B10: Northern Borders | C10: SA-08 | D10: Arar | E10: =COUNTIF(Governorates!B:B,A10) -> 4 | F10: =COUNTIF(Centers!B:B,A10) -> 28 | G10: =E10+F10 -> 32
A11: 10 | B11: Jazan | C11: SA-09 | D11: Jazan | E11: =COUNTIF(Governorates!B:B,A11) -> 17 | F11: =COUNTIF(Centers!B:B,A11) -> 39 | G11: =E11+F11 -> 56
A12: 11 | B12: Najran | C12: SA-10 | D12: Najran | E12: =COUNTIF(Governorates!B:B,A12) -> 7 | F12: =COUNTIF(Centers!B:B,A12) -> 51 | G12: =E12+F12 -> 58
A13: 12 | B13: Al-Baha | C13: SA-11 | D13: Al-Baha | E13: =COUNTIF(Governorates!B:B,A13) -> 10 | F13: =COUNTIF(Centers!B:B,A13) -> 42 | G13: =E13+F13 -> 52
A14: 13 | B14: Al-Jouf | C14: SA-12 | D14: Sakaka | E14: =COUNTIF(Governorates!B:B,A14) -> 4 | F14: =COUNTIF(Centers!B:B,A14) -> 33 | G14: =E14+F14 -> 37

Sheet Governorates
A1: Gov Code | B1: Region Code | C1: Region | D1: Governorate | E1: Category | F1: Centers | G1: Notes
A2: 0101 | B2: 1 | C2: Riyadh | D2: Riyadh | E2: Amanah (Region capital) | F2: =COUNTIF(Centers!D:D,A2) -> 6
A3: 0102 | B3: 1 | C3: Riyadh | D3: Ad-Diriyah | E3: Category A | F3: =COUNTIF(Centers!D:D,A3) -> 6
A4: 0103 | B4: 1 | C4: Riyadh | D4: Al-Kharj | E4: Category A | F4: =COUNTIF(Centers!D:D,A4) -> 20
A5: 0104 | B5: 1 | C5: Riyadh | D5: Ad-Dawadmi | E5: Category A | F5: =COUNTIF(Centers!D:D,A5) -> 104
A6: 0105 | B6: 1 | C6: Riyadh | D6: Al-Majma'ah | E6: Category A | F6: =COUNTIF(Centers!D:D,A6) -> 36
A7: 0106 | B7: 1 | C7: Riyadh | D7: Al-Quwayiyah | E7: Category A | F7: =COUNTIF(Centers!D:D,A7) -> 48
A8: 0107 | B8: 1 | C8: Riyadh | D8: Wadi Ad-Dawasir | E8: Category A | F8: =COUNTIF(Centers!D:D,A8) -> 9
A9: 0108 | B9: 1 | C9: Riyadh | D9: Al-Aflaj | E9: Category A | F9: =COUNTIF(Centers!D:D,A9) -> 28
A10: 0109 | B10: 1 | C10: Riyadh | D10: Az-Zulfi | E10: Category A | F10: =COUNTIF(Centers!D:D,A10) -> 5
A11: 0110 | B11: 1 | C11: Riyadh | D11: Shaqra | E11: Category A | F11: =COUNTIF(Centers!D:D,A11) -> 11
A12: 0111 | B12: 1 | C12: Riyadh | D12: Hotat Bani Tamim | E12: Category A | F12: =COUNTIF(Centers!D:D,A12) -> 8
A13: 0112 | B13: 1 | C13: Riyadh | D13: Afif | E13: Category A | F13: =COUNTIF(Centers!D:D,A13) -> 31
... A22: 0121 | B22: 1 | C22: Riyadh | D22: Marat | E22: Category B | F22: =COUNTIF(Centers!D:D,A22) -> 4
A23: 0122 | B23: 1 | C23: Riyadh | D23: Ad-Dilam | E23: Category B | F23: =COUNTIF(Centers!D:D,A23) -> 7 | G23: Newly established governorate (upgraded from a center)
A24: 0123 | B24: 1 | C24: Riyadh | D24: Ar-Rayn | E24: Category B | F24: =COUNTIF(Centers!D:D,A24) -> 42 | G24: Newly established governorate (upgraded from a center)
A25: 0201 | B25: 2 | C25: Makkah Al-Mukarramah | D25: Makkah Al-Mukarramah | E25: Amanah (Region capital) | F25: =COUNTIF(Centers!D:D,A25) -> 6
A26: 0202 | B26: 2 | C26: Makkah Al-Mukarramah | D26: Jeddah | E26: Category A | F26: =COUNTIF(Centers!D:D,A26) -> 1
A27: 0203 | B27: 2 | C27: Makkah Al-Mukarramah | D27: Taif | E27: Category A | F27: =COUNTIF(Centers!D:D,A27) -> 18
A28: 0204 | B28: 2 | C28: Makkah Al-Mukarramah | D28: Al-Qunfudhah | E28: Category A | F28: =COUNTIF(Centers!D:D,A28) -> 9
A29: 0205 | B29: 2 | C29: Makkah Al-Mukarramah | D29: Al-Lith | E29: Category A | F29: =COUNTIF(Centers!D:D,A29) -> 11
A30: 0206 | B30: 2 | C30: Makkah Al-Mukarramah | D30: Rabigh | E30: Category A | F30: =COUNTIF(Centers!D:D,A30) -> 6
A31: 0207 | B31: 2 | C31: Makkah Al-Mukarramah | D31: Al-Jumum | E31: Category B | F31: =COUNTIF(Centers!D:D,A31) -> 8
A32: 0208 | B32: 2 | C32: Makkah Al-Mukarramah | D32: Khulais | E32: Category A | F32: =COUNTIF(Centers!D:D,A32) -> 9
A33: 0209 | B33: 2 | C33: Makkah Al-Mukarramah | D33: Al-Kamil | E33: Category B | F33: =COUNTIF(Centers!D:D,A33) -> 4
A34: 0210 | B34: 2 | C34: Makkah Al-Mukarramah | D34: Al-Khurmah | E34: Category A | F34: =COUNTIF(Centers!D:D,A34) -> 3
A35: 0211 | B35: 2 | C35: Makkah Al-Mukarramah | D35: Ranyah | E35: Category A | F35: =COUNTIF(Centers!D:D,A35) -> 7
A36: 0212 | B36: 2 | C36: Makkah Al-Mukarramah | D36: Turbah | E36: Category A | F36: =COUNTIF(Centers!D:D,A36) -> 9
A37: 0213 | B37: 2 | C37: Makkah Al-Mukarramah | D37: Bahrah | E37: Category B | F37: =COUNTIF(Centers!D:D,A37) -> 4 | G37: Newly established; listed in the source as a center — classification corrected to governorate
A38: 0214 | B38: 2 | C38: Makkah Al-Mukarramah | D38: Al-Muwayh | E38: Category B | F38: =COUNTIF(Centers!D:D,A38) -> 17
A39: 0215 | B39: 2 | C39: Makkah Al-Mukarramah | D39: Maysan | E39: Category B | F39: =COUNTIF(Centers!D:D,A39) -> 6
A40: 0216 | B40: 2 | C40: Makkah Al-Mukarramah | D40: Al-Ardiyat | E40: Category B | F40: =COUNTIF(Centers!D:D,A40) -> 4
A41: 0217 | B41: 2 | C41: Makkah Al-Mukarramah | D41: Adham | E41: Category B | F41: =COUNTIF(Centers!D:D,A41) -> 4
A42: 0301 | B42: 3 | C42: Madinah Al-Munawwarah | D42: Madinah Al-Munawwarah | E42: Amanah (Region capital) | F42: =COUNTIF(Centers!D:D,A42) -> 16
A43: 0302 | B43: 3 | C43: Madinah Al-Munawwarah | D43: Yanbu | E43: Category A | F43: =COUNTIF(Centers!D:D,A43) -> 11
A44: 0303 | B44: 3 | C44: Madinah Al-Munawwarah | D44: AlUla | E44: Category A | F44: =COUNTIF(Centers!D:D,A44) -> 12
A45: 0304 | B45: 3 | C45: Madinah Al-Munawwarah | D45: Mahd Adh-Dhahab | E45: Category A | F45: =COUNTIF(Centers!D:D,A45) -> 18
A46: 0305 | B46: 3 | C46: Madinah Al-Munawwarah | D46: Badr | E46: Category B | F46: =COUNTIF(Centers!D:D,A46) -> 8
A47: 0306 | B47: 3 | C47: Madinah Al-Munawwarah | D47: Khaybar | E47: Category B | F47: =COUNTIF(Centers!D:D,A47) -> 9
A48: 0307 | B48: 3 | C48: Madinah Al-Munawwarah | D48: Al-Hanakiyah | E48: Category A | F48: =COUNTIF(Centers!D:D,A48) -> 10
...

Sheet Centers
A1: Center Code | B1: Region Code | C1: Region | D1: Gov Code | E1: Parent Governorate | F1: Center | G1: Center Category
A2: 0101-001 | B2: 1 | C2: Riyadh | D2: 0101 | E2: Riyadh | F2: Irqah | G2: Category A
A3: 0101-002 | B3: 1 | C3: Riyadh | D3: 0101 | E3: Riyadh | F3: Al-Ha'ir | G3: Category A
A4: 0101-003 | B4: 1 | C4: Riyadh | D4: 0101 | E4: Riyadh | F4: Hit | G4: Category A
A5: 0101-004 | B5: 1 | C5: Riyadh | D5: 0101 | E5: Riyadh | F5: Banban | G5: Category B
A6: 0101-005 | B6: 1 | C6: Riyadh | D6: 0101 | E6: Riyadh | F6: Al-Ammajiyah | G6: Category B
A7: 0101-006 | B7: 1 | C7: Riyadh | D7: 0101 | E7: Riyadh | F7: Dubayyan | G7: Category B
A8: 0102-001 | B8: 1 | C8: Riyadh | D8: 0102 | E8: Ad-Diriyah | F8: Al-Uyaynah wa Al-Jubaylah | G8: Category A
A9: 0102-002 | B9: 1 | C9: Riyadh | D9: 0102 | E9: Ad-Diriyah | F9: Al-Ammariyah | G9: Category A
A10: 0102-003 | B10: 1 | C10: Riyadh | D10: 0102 | E10: Ad-Diriyah | F10: Bawdah | G10: Category B
A11: 0102-004 | B11: 1 | C11: Riyadh | D11: 0102 | E11: Ad-Diriyah | F11: Sultanah | G11: Category A
A12: 0102-005 | B12: 1 | C12: Riyadh | D12: 0102 | E12: Ad-Diriyah | F12: Hazwa | G12: Category B
A13: 0102-006 | B13: 1 | C13: Riyadh | D13: 0102 | E13: Ad-Diriyah | F13: Sadus | G13: Category A
... A1405: 1304-006 | B1405: 13 | C1405: Al-Jouf | D1405: 1304 | E1405: Tabarjal | F1405: Thaniyat Umm Nukhaylah | G1405: Category B

Sheet References
A1: # | B1: Source | C1: Description & intended use | D1: URL
A2: 1 | B2: Regions System — Royal Order No. (A/92), 1412H / 1992 | C2: The statutory basis of the administrative division: regions, Category A/B governorates, and centers. Reference: National Center for Documents & Archives. | D2: https://ncar.gov.sa
A3: 2 | B3: Ministry of Interior — Agency for Regions Affairs | C3: The official list of governorates under each region. | D3: https://www.moi.gov.sa
A4: 3 | B4: Coding Directory of Regions, Governorates & Centers — National Center for Records (NCAR) | C4: The officially adopted coding for regions, governorates, and centers. | D4: http://ncar.gov.sa/Encoding/Regions
A5: 4 | B5: General Authority for Statistics (GASTAT) — statistics | C5: Source of governorate/center counts and their categories. | D5: https://www.stats.gov.sa/en/97
A6: 5 | B6: OpenStreetMap Wiki — Saudi governorates list | C6: The detailed list used in preparing this file. | D6: https://wiki.openstreetmap.org/wiki/Saudi_Arabia
A7: 6 | B7: Saudipedia — Administrative division of Saudi Arabia | C7: A current documentary reference: 13 regions, 150 governorates. | D7: https://saudipedia.com
A8: 7 | B8: National Open Data Portal | C8: Open government datasets for the administrative divisions. | D8: https://open.data.gov.sa
A9: 8 | B9: geoBoundaries — SAU ADM1/ADM2 | C9: Open geographic boundaries (GeoJSON / Shapefiles). | D9: https://www.geoboundaries.org/countryDownloads.html
A10: 9 | B10: HDX / OCHA — Saudi Arabia Administrative Boundaries | C10: Standardised administrative boundaries with P-codes. | D10: https://data.humdata.org/dataset/cod-ab-sau
A11: 10 | B11: GADM — Saudi Arabia | C11: An additional alternative for level-1 and level-2 boundaries. | D11: https://gadm.org/download_country.html
A12: 11 | B12: ISO 3166-2:SA | C12: The international region codes used in this file. | D12: https://www.iso.org/obp/ui/#iso:code:3166:SA
