Workbook

Sheet Geocoding Guide
A1: Geocoding Guide — Center-level Lat/Long/Radius for RIO Geo-fencing
A3: Why this sheet exists
A4: Official lat/long/radius data are not available for the 1,404 markaz (centers) in this workbook. No open dataset (HDX COD-AB, geoBoundaries) covers Saudi Arabia below region/admin1 level, so markaz-level coordinates have to be built rather than downloaded in one file.
A6: What's been added to this workbook
A7: - Centers sheet: Governorate (EN) and Region (EN) lookup columns, a ready-made 'Geocoding Query' string per row (Arabic center name + Arabic governorate + 'Saudi Arabia'), and empty Latitude / Longitude / Radius (m) / Geocode Status columns for the dev team's pipeline to populate.
A8: - Governorates sheet: same Latitude/Longitude columns added at governorate-capital level, with ONE verified example filled in (Ad-Dawadmi, highlighted yellow) to show the expected format and confirm the approach works for well-documented towns.
A10: Recommended pipeline (for the dev team to run — not done manually here)
A11: 1. Batch-geocode the 'Geocoding Query' column using OpenStreetMap Nominatim (free, rate-limited to ~1 request/second, needs a valid User-Agent) or Google Maps Geocoding API (paid, higher accuracy, better Arabic handling) — either works, Google is more reliable for small/rural place names.
A12: 2. Write the returned lat/long into columns K and L, and mark column N with 'Geocoded - high confidence', 'Geocoded - low confidence (verify)', or 'No match found'.
A13: 3. Expect gaps: small or newly-designated markaz (KSA has added many centers/governorates in recent years) may not appear in any open gazetteer yet, or only under a different Arabic spelling. For 'No match found' rows, fall back to the parent governorate's coordinates as a placeholder until a manual check is done.
A14: 4. Prioritize the centers that actually have active pilot organizations/villages on the RIO platform first — geocoding all 1,404 kingdom-wide is a bulk job that doesn't need to block the pilot.
A16: On radius
... A25: These are all provincial-capital CITIES - large, well-documented places with a single unambiguous Wikipedia entry. That's the easy 14 of 150 governorates. The other ~136 governorates (smaller towns) and all 1,404 markaz/centers will have much lower hit rates through manual search - many won't have an English Wikipedia page at all, which is exactly why the batch pipeline (Nominatim/Google Geocoding API against the 'Geocoding Query' column) is still the right approach for the rest, rather than continuing one search per row.

Sheet اقرأني ReadMe
B2: الدليل الجغرافي المرجعي للمملكة العربية السعودية
B3: KSA Geographic Reference — Regions, Governorates & Centers (for GIS / map development)
B5: الغرض | Purpose | C5: ملف مرجعي موحّد للتقسيمات الإدارية الرسمية للمملكة (منطقة ← محافظة ← مركز) لاستخدامه من قبل الفريق التقني في بناء طبقات الخريطة وقاعدة البيانات الجغرافية.
B6: الهيكل | Structure | C6: 3 مستويات إدارية وفق نظام المناطق (الأمر الملكي أ/92 لعام 1412هـ/1992م): 13 منطقة إدارية، 150 محافظة (شاملة أمانات عواصم المناطق)، 1,404 مركز (مراكز فئة أ وفئة ب).
B7: أوراق الملف | Sheets | C7: 1) المناطق Regions: الرموز الإحصائية ورموز ISO والعواصم. 2) المحافظات Governorates: بالعربية والإنجليزية مع الفئة والرمز. 3) المراكز Centers: كل مركز مرتبطاً بمحافظته ومنطقته. 4) المراجع References: المصادر الرسمية وروابط بيانات الحدود الجغرافية (GeoJSON/Shapefiles).
B8: الرموز | Coding | C8: رمز المنطقة (1–13) وفق ترتيب الهيئة العامة للإحصاء. رمز المحافظة = رمز المنطقة + تسلسل (مثال: 0101 = الرياض/الرياض). رمز المركز = رمز المحافظة + تسلسل (0104-003). هذه الرموز داخلية للربط بين الأوراق ويمكن استبدالها بترميز المركز الوطني للسجلات (NCAR) عند الاعتماد النهائي.
B9: ملاحظات للفريق التقني | Notes for the tech team | C9: • المدن الرئيسية ليست مستوى إدارياً مستقلاً؛ فكل محافظة تُسمّى باسم مدينتها/حاضرتها، وعواصم المناطق مدرجة في ورقة المناطق. • أسماء المراكز واردة بالعربية فقط (المصدر الرسمي عربي)؛ للمطابقة الجغرافية استخدموا الاسم العربي. • للحدود المكانية (Polygons) استخدموا مصادر الحدود في ورقة المراجع (المستوى Admin1 = المناطق، Admin2 = المحافظات).
B10: تنبيهات دقة | Data caveats | C10: • عدد المحافظات يتغير بأوامر ملكية (118 ← 136 عام 2012 ← 150 حالياً)؛ أُدرجت المحافظات المستحدثة (مثل: العديد، تنومة، الحرجه، الأمواه، بحرة). • وردت "بحرة" في المصدر كمركز رغم ترقيتها محافظةً — صُحّح تصنيفها هنا. • وردت "الأمواه" في المصدر بإملاء "الا مواه". • يُنصح بمطابقة نهائية مع دليل ترميز NCAR وبوابة وزارة الداخلية قبل الإطلاق.
B11: آخر تحديث | Last updated | C11: 07 يوليو 2026 — أعدّته أميرة خليل بالاستناد إلى المصادر المدرجة في ورقة المراجع.

Sheet المناطق Regions
A1: رمز المنطقة Region Code | B1: المنطقة Region (AR) | C1: Region (EN) | D1: رمز ISO 3166-2 | E1: عاصمة المنطقة (مقر الإمارة) Capital (AR) | F1: Capital (EN) | G1: عدد المحافظات Governorates | H1: عدد المراكز Centers | I1: إجمالي الوحدات Total
A2: 1 | B2: الرياض | C2: Riyadh | D2: SA-01 | E2: الرياض | F2: Riyadh | G2: =COUNTIF('المحافظات Governorates'!C:C,B2) -> 23 | H2: =COUNTIF('المراكز Centers'!C:C,B2) -> 417 | I2: =G2+H2 -> 440
A3: 2 | B3: مكة المكرمة | C3: Makkah Al-Mukarramah | D3: SA-02 | E3: مكة المكرمة | F3: Makkah | G3: =COUNTIF('المحافظات Governorates'!C:C,B3) -> 17 | H3: =COUNTIF('المراكز Centers'!C:C,B3) -> 126 | I3: =G3+H3 -> 143
A4: 3 | B4: المدينة المنورة | C4: Madinah Al-Munawwarah | D4: SA-03 | E4: المدينة المنورة | F4: Madinah | G4: =COUNTIF('المحافظات Governorates'!C:C,B4) -> 9 | H4: =COUNTIF('المراكز Centers'!C:C,B4) -> 102 | I4: =G4+H4 -> 111
A5: 4 | B5: القصيم | C5: Al-Qassim | D5: SA-05 | E5: بريدة | F5: Buraydah | G5: =COUNTIF('المحافظات Governorates'!C:C,B5) -> 13 | H5: =COUNTIF('المراكز Centers'!C:C,B5) -> 141 | I5: =G5+H5 -> 154
A6: 5 | B6: المنطقة الشرقية | C6: Eastern Province | D6: SA-04 | E6: الدمام | F6: Dammam | G6: =COUNTIF('المحافظات Governorates'!C:C,B6) -> 12 | H6: =COUNTIF('المراكز Centers'!C:C,B6) -> 111 | I6: =G6+H6 -> 123
A7: 6 | B7: عسير | C7: Aseer | D7: SA-14 | E7: أبها | F7: Abha | G7: =COUNTIF('المحافظات Governorates'!C:C,B7) -> 18 | H7: =COUNTIF('المراكز Centers'!C:C,B7) -> 122 | I7: =G7+H7 -> 140
A8: 7 | B8: تبوك | C8: Tabuk | D8: SA-07 | E8: تبوك | F8: Tabuk | G8: =COUNTIF('المحافظات Governorates'!C:C,B8) -> 7 | H8: =COUNTIF('المراكز Centers'!C:C,B8) -> 85 | I8: =G8+H8 -> 92
A9: 8 | B9: حائل | C9: Hail | D9: SA-06 | E9: حائل | F9: Hail | G9: =COUNTIF('المحافظات Governorates'!C:C,B9) -> 9 | H9: =COUNTIF('المراكز Centers'!C:C,B9) -> 107 | I9: =G9+H9 -> 116
A10: 9 | B10: الحدود الشمالية | C10: Northern Borders | D10: SA-08 | E10: عرعر | F10: Arar | G10: =COUNTIF('المحافظات Governorates'!C:C,B10) -> 4 | H10: =COUNTIF('المراكز Centers'!C:C,B10) -> 28 | I10: =G10+H10 -> 32
A11: 10 | B11: جازان | C11: Jazan | D11: SA-09 | E11: جازان | F11: Jazan | G11: =COUNTIF('المحافظات Governorates'!C:C,B11) -> 17 | H11: =COUNTIF('المراكز Centers'!C:C,B11) -> 39 | I11: =G11+H11 -> 56
A12: 11 | B12: نجران | C12: Najran | D12: SA-10 | E12: نجران | F12: Najran | G12: =COUNTIF('المحافظات Governorates'!C:C,B12) -> 7 | H12: =COUNTIF('المراكز Centers'!C:C,B12) -> 51 | I12: =G12+H12 -> 58
A13: 12 | B13: الباحة | C13: Al-Baha | D13: SA-11 | E13: الباحة | F13: Al-Baha | G13: =COUNTIF('المحافظات Governorates'!C:C,B13) -> 10 | H13: =COUNTIF('المراكز Centers'!C:C,B13) -> 42 | I13: =G13+H13 -> 52
A14: 13 | B14: الجوف | C14: Al-Jouf | D14: SA-12 | E14: سكاكا | F14: Sakaka | G14: =COUNTIF('المحافظات Governorates'!C:C,B14) -> 4 | H14: =COUNTIF('المراكز Centers'!C:C,B14) -> 33 | I14: =G14+H14 -> 37
B15: الإجمالي Total | G15: =SUM(G2:G14) -> 150 | H15: =SUM(H2:H14) -> 1404 | I15: =SUM(I2:I14) -> 1554

Sheet المحافظات Governorates
A1: رمز المحافظة Gov Code | B1: رمز المنطقة Region Code | C1: المنطقة Region (AR) | D1: المحافظة Governorate (AR) | E1: Governorate (EN) | F1: الفئة Category (AR) | G1: Category (EN) | H1: عدد المراكز التابعة No. of Centers | I1: ملاحظات Notes | J1: خط العرض (عاصمة المحافظة) Latitude (Gov. capital) | K1: خط الطول (عاصمة المحافظة) Longitude (Gov. capital) | L1: المصدر Source
A2: 0101 | B2: 1 | C2: الرياض | D2: الرياض | E2: Riyadh | F2: أمانة (عاصمة المنطقة) | G2: Amanah (Region capital) | H2: =COUNTIF('المراكز Centers'!D:D,A2) -> 6 | J2: 24.7136 | K2: 46.6753 | L2: Well-established public coordinate for Riyadh city center
A3: 0102 | B3: 1 | C3: الرياض | D3: الدرعيه | E3: Ad-Diriyah | F3: فئة (أ) | G3: Category A | H3: =COUNTIF('المراكز Centers'!D:D,A3) -> 6
A4: 0103 | B4: 1 | C4: الرياض | D4: الخرج | E4: Al-Kharj | F4: فئة (أ) | G4: Category A | H4: =COUNTIF('المراكز Centers'!D:D,A4) -> 20
A5: 0104 | B5: 1 | C5: الرياض | D5: الدوادمى | E5: Ad-Dawadmi | F5: فئة (أ) | G5: Category A | H5: =COUNTIF('المراكز Centers'!D:D,A5) -> 104 | J5: 24.50772 | K5: 44.39237 | L5: Verified via web search, Aug 2026 (Wikipedia/GeoNames-derived) - town center, not markaz boundary
A6: 0105 | B6: 1 | C6: الرياض | D6: المجمعه | E6: Al-Majma'ah | F6: فئة (أ) | G6: Category A | H6: =COUNTIF('المراكز Centers'!D:D,A6) -> 36
A7: 0106 | B7: 1 | C7: الرياض | D7: القويعيه | E7: Al-Quwayiyah | F7: فئة (أ) | G7: Category A | H7: =COUNTIF('المراكز Centers'!D:D,A7) -> 48
A8: 0107 | B8: 1 | C8: الرياض | D8: وادى الدواسر | E8: Wadi Ad-Dawasir | F8: فئة (أ) | G8: Category A | H8: =COUNTIF('المراكز Centers'!D:D,A8) -> 9
A9: 0108 | B9: 1 | C9: الرياض | D9: الافلاج | E9: Al-Aflaj | F9: فئة (أ) | G9: Category A | H9: =COUNTIF('المراكز Centers'!D:D,A9) -> 28
A10: 0109 | B10: 1 | C10: الرياض | D10: الزلفى | E10: Az-Zulfi | F10: فئة (أ) | G10: Category A | H10: =COUNTIF('المراكز Centers'!D:D,A10) -> 5
A11: 0110 | B11: 1 | C11: الرياض | D11: شقراء | E11: Shaqra | F11: فئة (أ) | G11: Category A | H11: =COUNTIF('المراكز Centers'!D:D,A11) -> 11
A12: 0111 | B12: 1 | C12: الرياض | D12: حوطه بنى تميم | E12: Hotat Bani Tamim | F12: فئة (أ) | G12: Category A | H12: =COUNTIF('المراكز Centers'!D:D,A12) -> 8
A13: 0112 | B13: 1 | C13: الرياض | D13: عفيف | E13: Afif | F13: فئة (أ) | G13: Category A | H13: =COUNTIF('المراكز Centers'!D:D,A13) -> 31
A14: 0113 | B14: 1 | C14: الرياض | D14: السليل | E14: As-Sulayyil | F14: فئة (ب) | G14: Category B | H14: =COUNTIF('المراكز Centers'!D:D,A14) -> 4
A15: 0114 | B15: 1 | C15: الرياض | D15: ضرما | E15: Dhurma | F15: فئة (ب) | G15: Category B | H15: =COUNTIF('المراكز Centers'!D:D,A15) -> 7
A16: 0115 | B16: 1 | C16: الرياض | D16: المزاحميه | E16: Al-Muzahimiyah | F16: فئة (ب) | G16: Category B | H16: =COUNTIF('المراكز Centers'!D:D,A16) -> 8
A17: 0116 | B17: 1 | C17: الرياض | D17: رماح | E17: Rumah | F17: فئة (ب) | G17: Category B | H17: =COUNTIF('المراكز Centers'!D:D,A17) -> 10
... A22: 0121 | B22: 1 | C22: الرياض | D22: مرات | E22: Marat | F22: فئة (ب) | G22: Category B | H22: =COUNTIF('المراكز Centers'!D:D,A22) -> 4
A23: 0122 | B23: 1 | C23: الرياض | D23: الدلم | E23: Ad-Dilam | F23: فئة (ب) | G23: Category B | H23: =COUNTIF('المراكز Centers'!D:D,A23) -> 7 | I23: محافظة مستحدثة (رُقّيت من مركز)
A24: 0123 | B24: 1 | C24: الرياض | D24: الرين | E24: Ar-Rayn | F24: فئة (ب) | G24: Category B | H24: =COUNTIF('المراكز Centers'!D:D,A24) -> 42 | I24: محافظة مستحدثة (رُقّيت من مركز)
A25: 0201 | B25: 2 | C25: مكة المكرمة | D25: مكة المكرمة | E25: Makkah Al-Mukarramah | F25: أمانة (عاصمة المنطقة) | G25: Amanah (Region capital) | H25: =COUNTIF('المراكز Centers'!D:D,A25) -> 6 | J25: 21.42664 | K25: 39.82563 | L25: Verified via web search, Aug 2026 (geodatos.net/Wikipedia)
A26: 0202 | B26: 2 | C26: مكة المكرمة | D26: جدة | E26: Jeddah | F26: فئة (أ) | G26: Category A | H26: =COUNTIF('المراكز Centers'!D:D,A26) -> 1 | J26: 21.54333 | K26: 39.17278 | L26: Verified via web search, Aug 2026 (Wikipedia infobox)
A27: 0203 | B27: 2 | C27: مكة المكرمة | D27: الطائف | E27: Taif | F27: فئة (أ) | G27: Category A | H27: =COUNTIF('المراكز Centers'!D:D,A27) -> 18
A28: 0204 | B28: 2 | C28: مكة المكرمة | D28: القنفذه | E28: Al-Qunfudhah | F28: فئة (أ) | G28: Category A | H28: =COUNTIF('المراكز Centers'!D:D,A28) -> 9
A29: 0205 | B29: 2 | C29: مكة المكرمة | D29: الليث | E29: Al-Lith | F29: فئة (أ) | G29: Category A | H29: =COUNTIF('المراكز Centers'!D:D,A29) -> 11
A30: 0206 | B30: 2 | C30: مكة المكرمة | D30: رابغ | E30: Rabigh | F30: فئة (أ) | G30: Category A | H30: =COUNTIF('المراكز Centers'!D:D,A30) -> 6
A31: 0207 | B31: 2 | C31: مكة المكرمة | D31: الجموم | E31: Al-Jumum | F31: فئة (ب) | G31: Category B | H31: =COUNTIF('المراكز Centers'!D:D,A31) -> 8
A32: 0208 | B32: 2 | C32: مكة المكرمة | D32: خليص | E32: Khulais | F32: فئة (أ) | G32: Category A | H32: =COUNTIF('المراكز Centers'!D:D,A32) -> 9
A33: 0209 | B33: 2 | C33: مكة المكرمة | D33: الكامل | E33: Al-Kamil | F33: فئة (ب) | G33: Category B | H33: =COUNTIF('المراكز Centers'!D:D,A33) -> 4
A34: 0210 | B34: 2 | C34: مكة المكرمة | D34: الخرمة | E34: Al-Khurmah | F34: فئة (أ) | G34: Category A | H34: =COUNTIF('المراكز Centers'!D:D,A34) -> 3
A35: 0211 | B35: 2 | C35: مكة المكرمة | D35: رنيه | E35: Ranyah | F35: فئة (أ) | G35: Category A | H35: =COUNTIF('المراكز Centers'!D:D,A35) -> 7
A36: 0212 | B36: 2 | C36: مكة المكرمة | D36: تربه | E36: Turbah | F36: فئة (أ) | G36: Category A | H36: =COUNTIF('المراكز Centers'!D:D,A36) -> 9
A37: 0213 | B37: 2 | C37: مكة المكرمة | D37: بحرة | E37: Bahrah | F37: فئة (ب) | G37: Category B | H37: =COUNTIF('المراكز Centers'!D:D,A37) -> 4 | I37: مستحدثة؛ وردت في المصدر كمركز وصُحّح تصنيفها محافظة
A38: 0214 | B38: 2 | C38: مكة المكرمة | D38: المويه | E38: Al-Muwayh | F38: فئة (ب) | G38: Category B | H38: =COUNTIF('المراكز Centers'!D:D,A38) -> 17
A39: 0215 | B39: 2 | C39: مكة المكرمة | D39: ميسان | E39: Maysan | F39: فئة (ب) | G39: Category B | H39: =COUNTIF('المراكز Centers'!D:D,A39) -> 6
A40: 0216 | B40: 2 | C40: مكة المكرمة | D40: العرضيات | E40: Al-Ardiyat | F40: فئة (ب) | G40: Category B | H40: =COUNTIF('المراكز Centers'!D:D,A40) -> 4
A41: 0217 | B41: 2 | C41: مكة المكرمة | D41: أضم | E41: Adham | F41: فئة (ب) | G41: Category B | H41: =COUNTIF('المراكز Centers'!D:D,A41) -> 4
A42: 0301 | B42: 3 | C42: المدينة المنورة | D42: المدينة المنورة | E42: Madinah Al-Munawwarah | F42: أمانة (عاصمة المنطقة) | G42: Amanah (Region capital) | H42: =COUNTIF('المراكز Centers'!D:D,A42) -> 16 | J42: 24.47 | K42: 39.61 | L42: Verified via web search, Aug 2026 (Wikipedia infobox)
A43: 0302 | B43: 3 | C43: المدينة المنورة | D43: ينبع | E43: Yanbu | F43: فئة (أ) | G43: Category A | H43: =COUNTIF('المراكز Centers'!D:D,A43) -> 11
A44: 0303 | B44: 3 | C44: المدينة المنورة | D44: العلا | E44: AlUla | F44: فئة (أ) | G44: Category A | H44: =COUNTIF('المراكز Centers'!D:D,A44) -> 12
...

Sheet المراكز Centers
A1: رمز المركز Center Code | B1: رمز المنطقة Region Code | C1: المنطقة Region (AR) | D1: رمز المحافظة Gov Code | E1: المحافظة التابع لها Parent Governorate (AR) | F1: المركز Center (AR) | G1: فئة المركز Center Category | H1: المحافظة Governorate (EN) | I1: المنطقة Region (EN) | J1: استعلام الترميز الجغرافي Geocoding Query | K1: خط العرض Latitude | L1: خط الطول Longitude | M1: نصف القطر (متر) Radius (m) | N1: حالة الترميز الجغرافي Geocode Status
A2: 0101-001 | B2: 1 | C2: الرياض | D2: 0101 | E2: الرياض | F2: عرقه | G2: فئة (أ) | H2: =IFERROR(INDEX('المحافظات Governorates'!$E$2:$E$151,MATCH(D2,'المحافظات Governorates'!$A$2:$A$151,0)),"") -> Riyadh | I2: =IFERROR(INDEX('المناطق Regions'!$C$2:$C$15,MATCH(B2,'المناطق Regions'!$A$2:$A$15,0)),"") -> Riyadh | J2: =F2&", "&E2&", Saudi Arabia" -> عرقه, الرياض, Saudi Arabia | K2: 24.684146 | L2: 46.582611 | M2: 2000 | N2: geocoded
A3: 0101-002 | B3: 1 | C3: الرياض | D3: 0101 | E3: الرياض | F3: الحائر | G3: فئة (أ) | H3: =IFERROR(INDEX('المحافظات Governorates'!$E$2:$E$151,MATCH(D3,'المحافظات Governorates'!$A$2:$A$151,0)),"") -> Riyadh | I3: =IFERROR(INDEX('المناطق Regions'!$C$2:$C$15,MATCH(B3,'المناطق Regions'!$A$2:$A$15,0)),"") -> Riyadh | J3: =F3&", "&E3&", Saudi Arabia" -> الحائر, الرياض, Saudi Arabia | K3: 24.402222 | L3: 46.836667 | M3: 2000 | N3: geocoded
A4: 0101-003 | B4: 1 | C4: الرياض | D4: 0101 | E4: الرياض | F4: هيت | G4: فئة (أ) | H4: =IFERROR(INDEX('المحافظات Governorates'!$E$2:$E$151,MATCH(D4,'المحافظات Governorates'!$A$2:$A$151,0)),"") -> Riyadh | I4: =IFERROR(INDEX('المناطق Regions'!$C$2:$C$15,MATCH(B4,'المناطق Regions'!$A$2:$A$15,0)),"") -> Riyadh | J4: =F4&", "&E4&", Saudi Arabia" -> هيت, الرياض, Saudi Arabia | K4: 24.460556 | L4: 47.0025 | M4: 2000 | N4: geocoded
A5: 0101-004 | B5: 1 | C5: الرياض | D5: 0101 | E5: الرياض | F5: بنبان | G5: فئة (ب) | H5: =IFERROR(INDEX('المحافظات Governorates'!$E$2:$E$151,MATCH(D5,'المحافظات Governorates'!$A$2:$A$151,0)),"") -> Riyadh | I5: =IFERROR(INDEX('المناطق Regions'!$C$2:$C$15,MATCH(B5,'المناطق Regions'!$A$2:$A$15,0)),"") -> Riyadh | J5: =F5&", "&E5&", Saudi Arabia" -> بنبان, الرياض, Saudi Arabia | K5: 25.001667 | L5: 46.588056 | M5: 2000 | N5: geocoded
A6: 0101-005 | B6: 1 | C6: الرياض | D6: 0101 | E6: الرياض | F6: العماجية | G6: فئة (ب) | H6: =IFERROR(INDEX('المحافظات Governorates'!$E$2:$E$151,MATCH(D6,'المحافظات Governorates'!$A$2:$A$151,0)),"") -> Riyadh | I6: =IFERROR(INDEX('المناطق Regions'!$C$2:$C$15,MATCH(B6,'المناطق Regions'!$A$2:$A$15,0)),"") -> Riyadh | J6: =F6&", "&E6&", Saudi Arabia" -> العماجية, الرياض, Saudi Arabia | K6: 24.440166 | L6: 46.978746 | M6: 2000 | N6: geocoded
A7: 0101-006 | B7: 1 | C7: الرياض | D7: 0101 | E7: الرياض | F7: دبيان | G7: فئة (ب) | H7: =IFERROR(INDEX('المحافظات Governorates'!$E$2:$E$151,MATCH(D7,'المحافظات Governorates'!$A$2:$A$151,0)),"") -> Riyadh | I7: =IFERROR(INDEX('المناطق Regions'!$C$2:$C$15,MATCH(B7,'المناطق Regions'!$A$2:$A$15,0)),"") -> Riyadh | J7: =F7&", "&E7&", Saudi Arabia" -> دبيان, الرياض, Saudi Arabia | K7: 24.601468 | L7: 47.138515 | M7: 2000 | N7: geocoded
A8: 0102-001 | B8: 1 | C8: الرياض | D8: 0102 | E8: الدرعيه | F8: العيينة والجبيلة | G8: فئة (أ) | H8: =IFERROR(INDEX('المحافظات Governorates'!$E$2:$E$151,MATCH(D8,'المحافظات Governorates'!$A$2:$A$151,0)),"") -> Ad-Diriyah | I8: =IFERROR(INDEX('المناطق Regions'!$C$2:$C$15,MATCH(B8,'المناطق Regions'!$A$2:$A$15,0)),"") -> Riyadh | J8: =F8&", "&E8&", Saudi Arabia" -> العيينة والجبيلة, الدرعيه, Saudi Arabia | K8: 24.878069 | L8: 46.373483 | M8: 33712 | N8: approximate (governorate centre, ±34km)
A9: 0102-002 | B9: 1 | C9: الرياض | D9: 0102 | E9: الدرعيه | F9: العماريه | G9: فئة (أ) | H9: =IFERROR(INDEX('المحافظات Governorates'!$E$2:$E$151,MATCH(D9,'المحافظات Governorates'!$A$2:$A$151,0)),"") -> Ad-Diriyah | I9: =IFERROR(INDEX('المناطق Regions'!$C$2:$C$15,MATCH(B9,'المناطق Regions'!$A$2:$A$15,0)),"") -> Riyadh | J9: =F9&", "&E9&", Saudi Arabia" -> العماريه, الدرعيه, Saudi Arabia | K9: 24.794167 | L9: 46.423333 | M9: 2000 | N9: geocoded
A10: 0102-003 | B10: 1 | C10: الرياض | D10: 0102 | E10: الدرعيه | F10: بوضه | G10: فئة (ب) | H10: =IFERROR(INDEX('المحافظات Governorates'!$E$2:$E$151,MATCH(D10,'المحافظات Governorates'!$A$2:$A$151,0)),"") -> Ad-Diriyah | I10: =IFERROR(INDEX('المناطق Regions'!$C$2:$C$15,MATCH(B10,'المناطق Regions'!$A$2:$A$15,0)),"") -> Riyadh | J10: =F10&", "&E10&", Saudi Arabia" -> بوضه, الدرعيه, Saudi Arabia | K10: 24.898654 | L10: 46.299256 | M10: 2000 | N10: geocoded
A11: 0102-004 | B11: 1 | C11: الرياض | D11: 0102 | E11: الدرعيه | F11: سلطانة | G11: فئة (أ) | H11: =IFERROR(INDEX('المحافظات Governorates'!$E$2:$E$151,MATCH(D11,'المحافظات Governorates'!$A$2:$A$151,0)),"") -> Ad-Diriyah | I11: =IFERROR(INDEX('المناطق Regions'!$C$2:$C$15,MATCH(B11,'المناطق Regions'!$A$2:$A$15,0)),"") -> Riyadh | J11: =F11&", "&E11&", Saudi Arabia" -> سلطانة, الدرعيه, Saudi Arabia | K11: 24.878069 | L11: 46.373483 | M11: 33712 | N11: approximate (governorate centre, ±34km)
A12: 0102-005 | B12: 1 | C12: الرياض | D12: 0102 | E12: الدرعيه | F12: حزوى | G12: فئة (ب) | H12: =IFERROR(INDEX('المحافظات Governorates'!$E$2:$E$151,MATCH(D12,'المحافظات Governorates'!$A$2:$A$151,0)),"") -> Ad-Diriyah | I12: =IFERROR(INDEX('المناطق Regions'!$C$2:$C$15,MATCH(B12,'المناطق Regions'!$A$2:$A$15,0)),"") -> Riyadh | J12: =F12&", "&E12&", Saudi Arabia" -> حزوى, الدرعيه, Saudi Arabia | K12: 24.991605 | L12: 46.232075 | M12: 2000 | N12: geocoded
A13: 0102-006 | B13: 1 | C13: الرياض | D13: 0102 | E13: الدرعيه | F13: سدوس | G13: فئة (أ) | H13: =IFERROR(INDEX('المحافظات Governorates'!$E$2:$E$151,MATCH(D13,'المحافظات Governorates'!$A$2:$A$151,0)),"") -> Ad-Diriyah | I13: =IFERROR(INDEX('المناطق Regions'!$C$2:$C$15,MATCH(B13,'المناطق Regions'!$A$2:$A$15,0)),"") -> Riyadh | J13: =F13&", "&E13&", Saudi Arabia" -> سدوس, الدرعيه, Saudi Arabia | K13: 24.991667 | L13: 46.2075 | M13: 2000 | N13: geocoded
... A517: 0214-003 | B517: 2 | C517: مكة المكرمة | D517: 0214 | E517: المويه | F517: الحفر | G517: فئة (ب) | H517: =IFERROR(INDEX('المحافظات Governorates'!$E$2:$E$151,MATCH(D517,'المحافظات Governorates'!$A$2:$A$151,0)),"") -> Al-Muwayh | I517: =IFERROR(INDEX('المناطق Regions'!$C$2:$C$15,MATCH(B517,'المناطق Regions'!$A$2:$A$15,0)),"") -> Makkah Al-Mukarramah | J517: =F517&", "&E517&", Saudi Arabia" -> الحفر, المويه, Saudi Arabia | K517: 22.831667 | L517: 41.118889 | M517: 2000 | N517: geocoded (governorate not verifiable)
A518: 0214-004 | B518: 2 | C518: مكة المكرمة | D518: 0214 | E518: المويه | F518: دغيبجه | G518: فئة (ب) | H518: =IFERROR(INDEX('المحافظات Governorates'!$E$2:$E$151,MATCH(D518,'المحافظات Governorates'!$A$2:$A$151,0)),"") -> Al-Muwayh | I518: =IFERROR(INDEX('المناطق Regions'!$C$2:$C$15,MATCH(B518,'المناطق Regions'!$A$2:$A$15,0)),"") -> Makkah Al-Mukarramah | J518: =F518&", "&E518&", Saudi Arabia" -> دغيبجه, المويه, Saudi Arabia | N518: not found
A519: 0214-005 | B519: 2 | C519: مكة المكرمة | D519: 0214 | E519: المويه | F519: الراغيه | G519: فئة (ب) | H519: =IFERROR(INDEX('المحافظات Governorates'!$E$2:$E$151,MATCH(D519,'المحافظات Governorates'!$A$2:$A$151,0)),"") -> Al-Muwayh | I519: =IFERROR(INDEX('المناطق Regions'!$C$2:$C$15,MATCH(B519,'المناطق Regions'!$A$2:$A$15,0)),"") -> Makkah Al-Mukarramah | J519: =F519&", "&E519&", Saudi Arabia" -> الراغيه, المويه, Saudi Arabia | N519: not found
A520: 0214-006 | B520: 2 | C520: مكة المكرمة | D520: 0214 | E520: المويه | F520: مران | G520: فئة (ب) | H520: =IFERROR(INDEX('المحافظات Governorates'!$E$2:$E$151,MATCH(D520,'المحافظات Governorates'!$A$2:$A$151,0)),"") -> Al-Muwayh | I520: =IFERROR(INDEX('المناطق Regions'!$C$2:$C$15,MATCH(B520,'المناطق Regions'!$A$2:$A$15,0)),"") -> Makkah Al-Mukarramah | J520: =F520&", "&E520&", Saudi Arabia" -> مران, المويه, Saudi Arabia | K520: 22.63781 | L520: 41.381944 | M520: 2000 | N520: geocoded (governorate not verifiable)
A521: 0214-007 | B521: 2 | C521: مكة المكرمة | D521: 0214 | E521: المويه | F521: البحره | G521: فئة (ب) | H521: =IFERROR(INDEX('المحافظات Governorates'!$E$2:$E$151,MATCH(D521,'المحافظات Governorates'!$A$2:$A$151,0)),"") -> Al-Muwayh | I521: =IFERROR(INDEX('المناطق Regions'!$C$2:$C$15,MATCH(B521,'المناطق Regions'!$A$2:$A$15,0)),"") -> Makkah Al-Mukarramah | J521: =F521&", "&E521&", Saudi Arabia" -> البحره, المويه, Saudi Arabia | N521: not found
A522: 0214-008 | B522: 2 | C522: مكة المكرمة | D522: 0214 | E522: المويه | F522: الزربان | G522: فئة (أ) | H522: =IFERROR(INDEX('المحافظات Governorates'!$E$2:$E$151,MATCH(D522,'المحافظات Governorates'!$A$2:$A$151,0)),"") -> Al-Muwayh | I522: =IFERROR(INDEX('المناطق Regions'!$C$2:$C$15,MATCH(B522,'المناطق Regions'!$A$2:$A$15,0)),"") -> Makkah Al-Mukarramah | J522: =F522&", "&E522&", Saudi Arabia" -> الزربان, المويه, Saudi Arabia | K522: 22.819444 | L522: 41.145324 | M522: 2000 | N522: geocoded (governorate not verifiable)
A523: 0214-009 | B523: 2 | C523: مكة المكرمة | D523: 0214 | E523: المويه | F523: مشاش الطارف | G523: فئة (ب) | H523: =IFERROR(INDEX('المحافظات Governorates'!$E$2:$E$151,MATCH(D523,'المحافظات Governorates'!$A$2:$A$151,0)),"") -> Al-Muwayh | I523: =IFERROR(INDEX('المناطق Regions'!$C$2:$C$15,MATCH(B523,'المناطق Regions'!$A$2:$A$15,0)),"") -> Makkah Al-Mukarramah | J523: =F523&", "&E523&", Saudi Arabia" -> مشاش الطارف, المويه, Saudi Arabia | K523: 21.833217 | L523: 41.214867 | M523: 2000 | N523: geocoded (governorate not verifiable)
A524: 0214-010 | B524: 2 | C524: مكة المكرمة | D524: 0214 | E524: المويه | F524: الرفايع | G524: فئة (ب) | H524: =IFERROR(INDEX('المحافظات Governorates'!$E$2:$E$151,MATCH(D524,'المحافظات Governorates'!$A$2:$A$151,0)),"") -> Al-Muwayh | I524: =IFERROR(INDEX('المناطق Regions'!$C$2:$C$15,MATCH(B524,'المناطق Regions'!$A$2:$A$15,0)),"") -> Makkah Al-Mukarramah | J524: =F524&", "&E524&", Saudi Arabia" -> الرفايع, المويه, Saudi Arabia | K524: 23.384598 | L524: 41.404798 | M524: 2000 | N524: geocoded (governorate not verifiable)
A525: 0214-011 | B525: 2 | C525: مكة المكرمة | D525: 0214 | E525: المويه | F525: الرويليه الصهلوج | G525: فئة (ب) | H525: =IFERROR(INDEX('المحافظات Governorates'!$E$2:$E$151,MATCH(D525,'المحافظات Governorates'!$A$2:$A$151,0)),"") -> Al-Muwayh | I525: =IFERROR(INDEX('المناطق Regions'!$C$2:$C$15,MATCH(B525,'المناطق Regions'!$A$2:$A$15,0)),"") -> Makkah Al-Mukarramah | J525: =F525&", "&E525&", Saudi Arabia" -> الرويليه الصهلوج, المويه, Saudi Arabia | N525: not found
A526: 0214-012 | B526: 2 | C526: مكة المكرمة | D526: 0214 | E526: المويه | F526: ام الدوم | G526: فئة (أ) | H526: =IFERROR(INDEX('المحافظات Governorates'!$E$2:$E$151,MATCH(D526,'المحافظات Governorates'!$A$2:$A$151,0)),"") -> Al-Muwayh | I526: =IFERROR(INDEX('المناطق Regions'!$C$2:$C$15,MATCH(B526,'المناطق Regions'!$A$2:$A$15,0)),"") -> Makkah Al-Mukarramah | J526: =F526&", "&E526&", Saudi Arabia" -> ام الدوم, المويه, Saudi Arabia | K526: 22.62771 | L526: 41.353786 | M526: 2000 | N526: geocoded (governorate not verifiable)
A527: 0214-013 | B527: 2 | C527: مكة المكرمة | D527: 0214 | E527: المويه | F527: الركنه | G527: فئة (ب) | H527: =IFERROR(INDEX('المحافظات Governorates'!$E$2:$E$151,MATCH(D527,'المحافظات Governorates'!$A$2:$A$151,0)),"") -> Al-Muwayh | I527: =IFERROR(INDEX('المناطق Regions'!$C$2:$C$15,MATCH(B527,'المناطق Regions'!$A$2:$A$15,0)),"") -> Makkah Al-Mukarramah | J527: =F527&", "&E527&", Saudi Arabia" -> الركنه, المويه, Saudi Arabia | N527: not found
A528: 0214-014 | B528: 2 | C528: مكة المكرمة | D528: 0214 | E528: المويه | F528: العوالي | G528: فئة (ب) | H528: =IFERROR(INDEX('المحافظات Governorates'!$E$2:$E$151,MATCH(D528,'المحافظات Governorates'!$A$2:$A$151,0)),"") -> Al-Muwayh | I528: =IFERROR(INDEX('المناطق Regions'!$C$2:$C$15,MATCH(B528,'المناطق Regions'!$A$2:$A$15,0)),"") -> Makkah Al-Mukarramah | J528: =F528&", "&E528&", Saudi Arabia" -> العوالي, المويه, Saudi Arabia | K528: 22.81513 | L528: 41.131901 | M528: 2000 | N528: geocoded (governorate not verifiable)
A529: 0214-015 | B529: 2 | C529: مكة المكرمة | D529: 0214 | E529: المويه | F529: المزيرعه | G529: فئة (ب) | H529: =IFERROR(INDEX('المحافظات Governorates'!$E$2:$E$151,MATCH(D529,'المحافظات Governorates'!$A$2:$A$151,0)),"") -> Al-Muwayh | I529: =IFERROR(INDEX('المناطق Regions'!$C$2:$C$15,MATCH(B529,'المناطق Regions'!$A$2:$A$15,0)),"") -> Makkah Al-Mukarramah | J529: =F529&", "&E529&", Saudi Arabia" -> المزيرعه, المويه, Saudi Arabia | N529: not found
A530: 0214-016 | B530: 2 | C530: مكة المكرمة | D530: 0214 | E530: المويه | F530: النصائف | G530: فئة (ب) | H530: =IFERROR(INDEX('المحافظات Governorates'!$E$2:$E$151,MATCH(D530,'المحافظات Governorates'!$A$2:$A$151,0)),"") -> Al-Muwayh | I530: =IFERROR(INDEX('المناطق Regions'!$C$2:$C$15,MATCH(B530,'المناطق Regions'!$A$2:$A$15,0)),"") -> Makkah Al-Mukarramah | J530: =F530&", "&E530&", Saudi Arabia" -> النصائف, المويه, Saudi Arabia | K530: 23.093472 | L530: 41.808566 | M530: 2000 | N530: geocoded (governorate not verifiable)
A531: 0214-017 | B531: 2 | C531: مكة المكرمة | D531: 0214 | E531: المويه | F531: ملحه | G531: فئة (ب) | H531: =IFERROR(INDEX('المحافظات Governorates'!$E$2:$E$151,MATCH(D531,'المحافظات Governorates'!$A$2:$A$151,0)),"") -> Al-Muwayh | I531: =IFERROR(INDEX('المناطق Regions'!$C$2:$C$15,MATCH(B531,'المناطق Regions'!$A$2:$A$15,0)),"") -> Makkah Al-Mukarramah | J531: =F531&", "&E531&", Saudi Arabia" -> ملحه, المويه, Saudi Arabia | N531: not found
A532: 0215-001 | B532: 2 | C532: مكة المكرمة | D532: 0215 | E532: ميسان | F532: بني سعد | G532: فئة (أ) | H532: =IFERROR(INDEX('المحافظات Governorates'!$E$2:$E$151,MATCH(D532,'المحافظات Governorates'!$A$2:$A$151,0)),"") -> Maysan | I532: =IFERROR(INDEX('المناطق Regions'!$C$2:$C$15,MATCH(B532,'المناطق Regions'!$A$2:$A$15,0)),"") -> Makkah Al-Mukarramah | J532: =F532&", "&E532&", Saudi Arabia" -> بني سعد, ميسان, Saudi Arabia | K532: 20.946618 | L532: 40.809354 | M532: 2000 | N532: geocoded
A533: 0215-002 | B533: 2 | C533: مكة المكرمة | D533: 0215 | E533: ميسان | F533: القريع بني مالك | G533: فئة (أ) | H533: =IFERROR(INDEX('المحافظات Governorates'!$E$2:$E$151,MATCH(D533,'المحافظات Governorates'!$A$2:$A$151,0)),"") -> Maysan | I533: =IFERROR(INDEX('المناطق Regions'!$C$2:$C$15,MATCH(B533,'المناطق Regions'!$A$2:$A$15,0)),"") -> Makkah Al-Mukarramah | J533: =F533&", "&E533&", Saudi Arabia" -> القريع بني مالك, ميسان, Saudi Arabia | K533: 20.466674 | L533: 41.068731 | M533: 2000 | N533: geocoded
A534: 0215-003 | B534: 2 | C534: مكة المكرمة | D534: 0215 | E534: ميسان | F534: ثقيف | G534: فئة (أ) | H534: =IFERROR(INDEX('المحافظات Governorates'!$E$2:$E$151,MATCH(D534,'المحافظات Governorates'!$A$2:$A$151,0)),"") -> Maysan | I534: =IFERROR(INDEX('المناطق Regions'!$C$2:$C$15,MATCH(B534,'المناطق Regions'!$A$2:$A$15,0)),"") -> Makkah Al-Mukarramah | J534: =F534&", "&E534&", Saudi Arabia" -> ثقيف, ميسان, Saudi Arabia | K534: 20.831617 | L534: 41.025571 | M534: 76011 | N534: approximate (governorate centre, ±76km)
A535: 0215-004 | B535: 2 | C535: مكة المكرمة | D535: 0215 | E535: ميسان | F535: حداد بني مالك | G535: فئة (أ) | H535: =IFERROR(INDEX('المحافظات Governorates'!$E$2:$E$151,MATCH(D535,'المحافظات Governorates'!$A$2:$A$151,0)),"") -> Maysan | I535: =IFERROR(INDEX('المناطق Regions'!$C$2:$C$15,MATCH(B535,'المناطق Regions'!$A$2:$A$15,0)),"") -> Makkah Al-Mukarramah | J535: =F535&", "&E535&", Saudi Arabia" -> حداد بني مالك, ميسان, Saudi Arabia | K535: 20.59739 | L535: 41.050059 | M535: 2000 | N535: geocoded
A536: 0215-005 | B536: 2 | C536: مكة المكرمة | D536: 0215 | E536: ميسان | F536: ابوراكه | G536: فئة (أ) | H536: =IFERROR(INDEX('المحافظات Governorates'!$E$2:$E$151,MATCH(D536,'المحافظات Governorates'!$A$2:$A$151,0)),"") -> Maysan | I536: =IFERROR(INDEX('المناطق Regions'!$C$2:$C$15,MATCH(B536,'المناطق Regions'!$A$2:$A$15,0)),"") -> Makkah Al-Mukarramah | J536: =F536&", "&E536&", Saudi Arabia" -> ابوراكه, ميسان, Saudi Arabia | K536: 20.933994 | L536: 41.201434 | M536: 2000 | N536: geocoded
A537: 0215-006 | B537: 2 | C537: مكة المكرمة | D537: 0215 | E537: ميسان | F537: الصور | G537: فئة (ب) | H537: =IFERROR(INDEX('المحافظات Governorates'!$E$2:$E$151,MATCH(D537,'المحافظات Governorates'!$A$2:$A$151,0)),"") -> Maysan | I537: =IFERROR(INDEX('المناطق Regions'!$C$2:$C$15,MATCH(B537,'المناطق Regions'!$A$2:$A$15,0)),"") -> Makkah Al-Mukarramah | J537: =F537&", "&E537&", Saudi Arabia" -> الصور, ميسان, Saudi Arabia | K537: 20.881227 | L537: 40.981237 | M537: 2000 | N537: geocoded
A538: 0216-002 | B538: 2 | C538: مكة المكرمة | D538: 0216 | E538: العرضيات | F538: العرضيه الشماليه | G538: فئة (أ) | H538: =IFERROR(INDEX('المحافظات Governorates'!$E$2:$E$151,MATCH(D538,'المحافظات Governorates'!$A$2:$A$151,0)),"") -> Al-Ardiyat | I538: =IFERROR(INDEX('المناطق Regions'!$C$2:$C$15,MATCH(B538,'المناطق Regions'!$A$2:$A$15,0)),"") -> Makkah Al-Mukarramah | J538: =F538&", "&E538&", Saudi Arabia" -> العرضيه الشماليه, العرضيات, Saudi Arabia | K538: 19.424201 | L538: 41.716046 | M538: 43627 | N538: approximate (governorate centre, ±44km)
A539: 0216-003 | B539: 2 | C539: مكة المكرمة | D539: 0216 | E539: العرضيات | F539: العرضيه الجنوبية | G539: فئة (أ) | H539: =IFERROR(INDEX('المحافظات Governorates'!$E$2:$E$151,MATCH(D539,'المحافظات Governorates'!$A$2:$A$151,0)),"") -> Al-Ardiyat | I539: =IFERROR(INDEX('المناطق Regions'!$C$2:$C$15,MATCH(B539,'المناطق Regions'!$A$2:$A$15,0)),"") -> Makkah Al-Mukarramah | J539: =F539&", "&E539&", Saudi Arabia" -> العرضيه الجنوبية, العرضيات, Saudi Arabia | K539: 19.424201 | L539: 41.716046 | M539: 43627 | N539: approximate (governorate centre, ±44km)
A540: 0216-004 | B540: 2 | C540: مكة المكرمة | D540: 0216 | E540: العرضيات | F540: الويد | G540: فئة (ب) | H540: =IFERROR(INDEX('المحافظات Governorates'!$E$2:$E$151,MATCH(D540,'المحافظات Governorates'!$A$2:$A$151,0)),"") -> Al-Ardiyat | I540: =IFERROR(INDEX('المناطق Regions'!$C$2:$C$15,MATCH(B540,'المناطق Regions'!$A$2:$A$15,0)),"") -> Makkah Al-Mukarramah | J540: =F540&", "&E540&", Saudi Arabia" -> الويد, العرضيات, Saudi Arabia | K540: 19.424201 | L540: 41.716046 | M540: 43627 | N540: approximate (governorate centre, ±44km)
A541: 0217-001 | B541: 2 | C541: مكة المكرمة | D541: 0217 | E541: أضم | F541: سوق العين | G541: فئة (أ) | H541: =IFERROR(INDEX('المحافظات Governorates'!$E$2:$E$151,MATCH(D541,'المحافظات Governorates'!$A$2:$A$151,0)),"") -> Adham | I541: =IFERROR(INDEX('المناطق Regions'!$C$2:$C$15,MATCH(B541,'المناطق Regions'!$A$2:$A$15,0)),"") -> Makkah Al-Mukarramah | J541: =F541&", "&E541&", Saudi Arabia" -> سوق العين, أضم, Saudi Arabia | K541: 20.436175 | L541: 40.830231 | M541: 40000 | N541: approximate (governorate centre)
A542: 0217-002 | B542: 2 | C542: مكة المكرمة | D542: 0217 | E542: أضم | F542: الجائزه | G542: فئة (أ) | H542: =IFERROR(INDEX('المحافظات Governorates'!$E$2:$E$151,MATCH(D542,'المحافظات Governorates'!$A$2:$A$151,0)),"") -> Adham | I542: =IFERROR(INDEX('المناطق Regions'!$C$2:$C$15,MATCH(B542,'المناطق Regions'!$A$2:$A$15,0)),"") -> Makkah Al-Mukarramah | J542: =F542&", "&E542&", Saudi Arabia" -> الجائزه, أضم, Saudi Arabia | K542: 20.436175 | L542: 40.830231 | M542: 40000 | N542: approximate (governorate centre)
A543: 0217-003 | B543: 2 | C543: مكة المكرمة | D543: 0217 | E543: أضم | F543: المرقبان | G543: فئة (ب) | H543: =IFERROR(INDEX('المحافظات Governorates'!$E$2:$E$151,MATCH(D543,'المحافظات Governorates'!$A$2:$A$151,0)),"") -> Adham | I543: =IFERROR(INDEX('المناطق Regions'!$C$2:$C$15,MATCH(B543,'المناطق Regions'!$A$2:$A$15,0)),"") -> Makkah Al-Mukarramah | J543: =F543&", "&E543&", Saudi Arabia" -> المرقبان, أضم, Saudi Arabia | K543: 20.436175 | L543: 40.830231 | M543: 40000 | N543: approximate (governorate centre)
...

Sheet المراجع References
A1: # | B1: المصدر Source | C1: الوصف / الاستخدام Description & intended use | D1: الرابط URL
A2: 1 | B2: نظام المناطق — الأمر الملكي رقم (أ/92) وتعديله (أ/21) | C2: الأساس النظامي للتقسيم الإداري: المناطق والمحافظات فئة (أ) و(ب) والمراكز. المرجع: المركز الوطني للوثائق والمحفوظات | D2: https://ncar.gov.sa
A3: 2 | B3: وزارة الداخلية — وكالة الوزارة لشؤون المناطق: الإمارات ومحافظاتها | C3: القائمة الرسمية للمحافظات التابعة لكل إمارة منطقة | D3: https://www.moi.gov.sa
A4: 3 | B4: دليل ترميز المناطق والمحافظات والمراكز — المركز الوطني للسجلات (NCAR) | C4: الترميز الرسمي المعتمد للمناطق والمحافظات والمراكز — يُوصى باعتماده كمعرّف نهائي في قاعدة البيانات | D4: http://ncar.gov.sa/Encoding/Region
A5: 4 | B5: الهيئة العامة للإحصاء (GASTAT) — إحصاءات الخدمات الحكومية وتعداد 2022 | C5: مصدر أعداد المحافظات والمراكز وفئاتها (الجدول 33) وبيانات السكان لكل تقسيم إداري | D5: https://www.stats.gov.sa/en/97
A6: 5 | B6: OpenStreetMap Wiki — قائمة محافظات ومراكز السعودية (المستند إلى بيانات وزارة الداخلية وGASTAT) | C6: القائمة التفصيلية المستخدمة في هذا الملف (1,554 وحدة: محافظات ومراكز بفئاتها)، بصيغة قابلة للمعالجة | D6: https://wiki.openstreetmap.org/wiki/List_of_governorates_of_Saudi_Arabia
A7: 6 | B7: سعوديبيديا — التقسيم الإداري للسعودية | C7: مرجع توثيقي حديث: 13 منطقة، 150 محافظة، والمراكز؛ يوثّق آلية استحداث المحافظات والمراكز | D7: https://saudipedia.com
A8: 7 | B8: البوابة الوطنية للبيانات المفتوحة | C8: مجموعات بيانات حكومية مفتوحة للتقسيمات الإدارية والسكان | D8: https://open.data.gov.sa
A9: 8 | B9: geoBoundaries — SAU ADM1/ADM2 | C9: حدود جغرافية مفتوحة (GeoJSON/Shapefile) للمناطق (ADM1) والمحافظات (ADM2) — مناسبة لبناء طبقات الخريطة | D9: https://www.geoboundaries.org/countryDownloads.html
A10: 9 | B10: HDX / OCHA — Saudi Arabia Administrative Boundaries (COD-AB) | C10: حدود إدارية معيارية بأكواد P-codes للربط البرمجي بين الجداول والخرائط | D10: https://data.humdata.org/dataset/cod-ab-sau
A11: 10 | B11: GADM — Saudi Arabia | C11: بديل إضافي لحدود المستويين الأول والثاني بصيغ GeoPackage/Shapefile | D11: https://gadm.org/download_country.html
A12: 11 | B12: ISO 3166-2:SA | C12: رموز المناطق الدولية المستخدمة في ورقة المناطق (ملاحظة: عسير = SA-14 ولا يوجد SA-13) | D12: https://www.iso.org/obp/ui/#iso:code:3166:SA
